************* Module pip._internal.network.auth
/log/firmware/firmware/usr/lib/python3.8/site-packages/pip/_internal/network/auth.py:32:7: W0703: Catching too general exception Exception (broad-except)
/log/firmware/firmware/usr/lib/python3.8/site-packages/pip/_internal/network/auth.py:37:4: C0103: Constant name "keyring" doesn't conform to UPPER_CASE naming style (invalid-name)
/log/firmware/firmware/usr/lib/python3.8/site-packages/pip/_internal/network/auth.py:42:4: C0103: Constant name "keyring" doesn't conform to UPPER_CASE naming style (invalid-name)
/log/firmware/firmware/usr/lib/python3.8/site-packages/pip/_internal/network/auth.py:42:4: W0603: Using the global statement (global-statement)
/log/firmware/firmware/usr/lib/python3.8/site-packages/pip/_internal/network/auth.py:64:11: W0703: Catching too general exception Exception (broad-except)
/log/firmware/firmware/usr/lib/python3.8/site-packages/pip/_internal/network/auth.py:103:12: C0103: Variable name "u" doesn't conform to snake_case naming style (invalid-name)
/log/firmware/firmware/usr/lib/python3.8/site-packages/pip/_internal/network/auth.py:187:12: C0103: Variable name "un" doesn't conform to snake_case naming style (invalid-name)
/log/firmware/firmware/usr/lib/python3.8/site-packages/pip/_internal/network/auth.py:187:16: C0103: Variable name "pw" doesn't conform to snake_case naming style (invalid-name)
/log/firmware/firmware/usr/lib/python3.8/site-packages/pip/_internal/network/auth.py:230:4: R0201: Method could be a function (no-self-use)
/log/firmware/firmware/usr/lib/python3.8/site-packages/pip/_internal/network/auth.py:243:4: R0201: Method could be a function (no-self-use)
/log/firmware/firmware/usr/lib/python3.8/site-packages/pip/_internal/network/auth.py:283:8: W0104: Statement seems to have no effect (pointless-statement)
/log/firmware/firmware/usr/lib/python3.8/site-packages/pip/_internal/network/auth.py:302:0: W0613: Unused argument 'kwargs' (unused-argument)
/log/firmware/firmware/usr/lib/python3.8/site-packages/pip/_internal/network/auth.py:302:4: R0201: Method could be a function (no-self-use)
/log/firmware/firmware/usr/lib/python3.8/site-packages/pip/_internal/network/auth.py:322:19: W0703: Catching too general exception Exception (broad-except)
/log/firmware/firmware/usr/lib/python3.8/site-packages/pip/_internal/network/auth.py:310:0: W0613: Unused argument 'kwargs' (unused-argument)

-----------------------------------
Your code has been rated at 9.03/10

