************* Module asyncio.base_events
/log/firmware/firmware/usr/lib/python3.8/asyncio/base_events.py:52:0: R1707: Disallow trailing comma tuple (trailing-comma-tuple)
/log/firmware/firmware/usr/lib/python3.8/asyncio/base_events.py:660:0: C0325: Unnecessary parens after 'return' keyword (superfluous-parens)
/log/firmware/firmware/usr/lib/python3.8/asyncio/base_events.py:1:0: C0302: Too many lines in module (1884/1000) (too-many-lines)
/log/firmware/firmware/usr/lib/python3.8/asyncio/base_events.py:64:0: C0103: Constant name "_HAS_IPv6" doesn't conform to UPPER_CASE naming style (invalid-name)
/log/firmware/firmware/usr/lib/python3.8/asyncio/base_events.py:75:4: C0103: Variable name "cb" doesn't conform to snake_case naming style (invalid-name)
/log/firmware/firmware/usr/lib/python3.8/asyncio/base_events.py:75:9: W0212: Access to a protected member _callback of a client class (protected-access)
/log/firmware/firmware/usr/lib/python3.8/asyncio/base_events.py:76:4: R1705: Unnecessary "else" after "return" (no-else-return)
/log/firmware/firmware/usr/lib/python3.8/asyncio/base_events.py:83:0: C0103: Argument name "fd" doesn't conform to snake_case naming style (invalid-name)
/log/firmware/firmware/usr/lib/python3.8/asyncio/base_events.py:84:4: R1705: Unnecessary "elif" after "return" (no-else-return)
/log/firmware/firmware/usr/lib/python3.8/asyncio/base_events.py:93:4: R1720: Unnecessary "else" after "raise" (no-else-raise)
/log/firmware/firmware/usr/lib/python3.8/asyncio/base_events.py:99:12: W0707: Consider explicitly re-raising using the 'from' keyword (raise-missing-from)
/log/firmware/firmware/usr/lib/python3.8/asyncio/base_events.py:103:37: W0622: Redefining built-in 'type' (redefined-builtin)
/log/firmware/firmware/usr/lib/python3.8/asyncio/base_events.py:103:0: R0913: Too many arguments (7/5) (too-many-arguments)
/log/firmware/firmware/usr/lib/python3.8/asyncio/base_events.py:147:8: C0103: Variable name "af" doesn't conform to snake_case naming style (invalid-name)
/log/firmware/firmware/usr/lib/python3.8/asyncio/base_events.py:151:12: R1705: Unnecessary "else" after "return" (no-else-return)
/log/firmware/firmware/usr/lib/python3.8/asyncio/base_events.py:103:0: R1710: Either all return statements in a function should return an expression, or none of them should. (inconsistent-return-statements)
/log/firmware/firmware/usr/lib/python3.8/asyncio/base_events.py:103:0: R0911: Too many return statements (8/6) (too-many-return-statements)
/log/firmware/firmware/usr/lib/python3.8/asyncio/base_events.py:103:0: R0912: Too many branches (19/12) (too-many-branches)
/log/firmware/firmware/usr/lib/python3.8/asyncio/base_events.py:191:4: W0212: Access to a protected member _get_loop of a client class (protected-access)
/log/firmware/firmware/usr/lib/python3.8/asyncio/base_events.py:201:21: W0613: Unused argument 'sock' (unused-argument)
/log/firmware/firmware/usr/lib/python3.8/asyncio/base_events.py:228:4: R0201: Method could be a function (no-self-use)
/log/firmware/firmware/usr/lib/python3.8/asyncio/base_events.py:246:32: W0212: Access to a protected member _loop of a client class (protected-access)
/log/firmware/firmware/usr/lib/python3.8/asyncio/base_events.py:254:4: R0201: Method could be a function (no-self-use)
/log/firmware/firmware/usr/lib/python3.8/asyncio/base_events.py:257:4: R0201: Method could be a function (no-self-use)
/log/firmware/firmware/usr/lib/python3.8/asyncio/base_events.py:273:0: R0902: Too many instance attributes (10/7) (too-many-instance-attributes)
/log/firmware/firmware/usr/lib/python3.8/asyncio/base_events.py:275:4: R0913: Too many arguments (7/5) (too-many-arguments)
/log/firmware/firmware/usr/lib/python3.8/asyncio/base_events.py:314:12: W0212: Access to a protected member _start_serving of a client class (protected-access)
/log/firmware/firmware/usr/lib/python3.8/asyncio/base_events.py:337:12: W0212: Access to a protected member _stop_serving of a client class (protected-access)
/log/firmware/firmware/usr/lib/python3.8/asyncio/base_events.py:384:0: R0902: Too many instance attributes (18/7) (too-many-instance-attributes)
/log/firmware/firmware/usr/lib/python3.8/asyncio/base_events.py:432:15: W0212: Access to a protected member _source_traceback of a client class (protected-access)
/log/firmware/firmware/usr/lib/python3.8/asyncio/base_events.py:433:20: W0212: Access to a protected member _source_traceback of a client class (protected-access)
/log/firmware/firmware/usr/lib/python3.8/asyncio/base_events.py:436:12: W0212: Access to a protected member _set_task_name of a client class (protected-access)
/log/firmware/firmware/usr/lib/python3.8/asyncio/base_events.py:472:4: R0913: Too many arguments (6/5) (too-many-arguments)
/log/firmware/firmware/usr/lib/python3.8/asyncio/base_events.py:487:4: R0913: Too many arguments (9/5) (too-many-arguments)
/log/firmware/firmware/usr/lib/python3.8/asyncio/base_events.py:528:11: C1801: Do not use `len(SEQUENCE)` without comparison to determine if a sequence is empty (len-as-condition)
/log/firmware/firmware/usr/lib/python3.8/asyncio/base_events.py:553:11: W0212: Access to a protected member _get_running_loop of a client class (protected-access)
/log/firmware/firmware/usr/lib/python3.8/asyncio/base_events.py:568:12: W0212: Access to a protected member _set_running_loop of a client class (protected-access)
/log/firmware/firmware/usr/lib/python3.8/asyncio/base_events.py:576:12: W0212: Access to a protected member _set_running_loop of a client class (protected-access)
/log/firmware/firmware/usr/lib/python3.8/asyncio/base_events.py:599:12: W0212: Access to a protected member _log_destroy_pending of a client class (protected-access)
/log/firmware/firmware/usr/lib/python3.8/asyncio/base_events.py:662:4: R0201: Method could be a function (no-self-use)
/log/firmware/firmware/usr/lib/python3.8/asyncio/base_events.py:689:11: W0212: Access to a protected member _source_traceback of a client class (protected-access)
/log/firmware/firmware/usr/lib/python3.8/asyncio/base_events.py:690:16: W0212: Access to a protected member _source_traceback of a client class (protected-access)
/log/firmware/firmware/usr/lib/python3.8/asyncio/base_events.py:703:11: W0212: Access to a protected member _source_traceback of a client class (protected-access)
/log/firmware/firmware/usr/lib/python3.8/asyncio/base_events.py:704:16: W0212: Access to a protected member _source_traceback of a client class (protected-access)
/log/firmware/firmware/usr/lib/python3.8/asyncio/base_events.py:706:8: W0212: Access to a protected member _scheduled of a client class (protected-access)
/log/firmware/firmware/usr/lib/python3.8/asyncio/base_events.py:724:11: W0212: Access to a protected member _source_traceback of a client class (protected-access)
/log/firmware/firmware/usr/lib/python3.8/asyncio/base_events.py:725:16: W0212: Access to a protected member _source_traceback of a client class (protected-access)
/log/firmware/firmware/usr/lib/python3.8/asyncio/base_events.py:728:4: R0201: Method could be a function (no-self-use)
/log/firmware/firmware/usr/lib/python3.8/asyncio/base_events.py:740:11: W0212: Access to a protected member _source_traceback of a client class (protected-access)
/log/firmware/firmware/usr/lib/python3.8/asyncio/base_events.py:741:16: W0212: Access to a protected member _source_traceback of a client class (protected-access)
/log/firmware/firmware/usr/lib/python3.8/asyncio/base_events.py:768:11: W0212: Access to a protected member _source_traceback of a client class (protected-access)
/log/firmware/firmware/usr/lib/python3.8/asyncio/base_events.py:769:16: W0212: Access to a protected member _source_traceback of a client class (protected-access)
/log/firmware/firmware/usr/lib/python3.8/asyncio/base_events.py:794:53: W0622: Redefining built-in 'type' (redefined-builtin)
/log/firmware/firmware/usr/lib/python3.8/asyncio/base_events.py:794:4: R0913: Too many arguments (7/5) (too-many-arguments)
/log/firmware/firmware/usr/lib/python3.8/asyncio/base_events.py:807:8: C0103: Variable name "t0" doesn't conform to snake_case naming style (invalid-name)
/log/firmware/firmware/usr/lib/python3.8/asyncio/base_events.py:809:8: C0103: Variable name "dt" doesn't conform to snake_case naming style (invalid-name)
/log/firmware/firmware/usr/lib/python3.8/asyncio/base_events.py:819:36: W0622: Redefining built-in 'type' (redefined-builtin)
/log/firmware/firmware/usr/lib/python3.8/asyncio/base_events.py:840:8: W0612: Unused variable 'exc' (unused-variable)
/log/firmware/firmware/usr/lib/python3.8/asyncio/base_events.py:879:4: R0201: Method could be a function (no-self-use)
/log/firmware/firmware/usr/lib/python3.8/asyncio/base_events.py:900:34: W0621: Redefining name 'exceptions' from outer scope (line 41) (redefined-outer-name)
/log/firmware/firmware/usr/lib/python3.8/asyncio/base_events.py:938:15: W0621: Redefining name 'ssl' from outer scope (line 34) (redefined-outer-name)
/log/firmware/firmware/usr/lib/python3.8/asyncio/base_events.py:1005:12: W0621: Redefining name 'exceptions' from outer scope (line 41) (redefined-outer-name)
/log/firmware/firmware/usr/lib/python3.8/asyncio/base_events.py:936:4: R0914: Too many local variables (22/15) (too-many-locals)
/log/firmware/firmware/usr/lib/python3.8/asyncio/base_events.py:1024:16: R1720: Unnecessary "else" after "raise" (no-else-raise)
/log/firmware/firmware/usr/lib/python3.8/asyncio/base_events.py:936:4: R0912: Too many branches (24/12) (too-many-branches)
/log/firmware/firmware/usr/lib/python3.8/asyncio/base_events.py:936:4: R0915: Too many statements (52/50) (too-many-statements)
/log/firmware/firmware/usr/lib/python3.8/asyncio/base_events.py:1062:42: W0621: Redefining name 'ssl' from outer scope (line 34) (redefined-outer-name)
/log/firmware/firmware/usr/lib/python3.8/asyncio/base_events.py:1061:4: R0913: Too many arguments (7/5) (too-many-arguments)
/log/firmware/firmware/usr/lib/python3.8/asyncio/base_events.py:1114:23: W0212: Access to a protected member _SendfileMode of a client class (protected-access)
/log/firmware/firmware/usr/lib/python3.8/asyncio/base_events.py:1115:19: W0212: Access to a protected member _SendfileMode of a client class (protected-access)
/log/firmware/firmware/usr/lib/python3.8/asyncio/base_events.py:1118:19: W0212: Access to a protected member _SendfileMode of a client class (protected-access)
/log/firmware/firmware/usr/lib/python3.8/asyncio/base_events.py:1122:12: W0612: Unused variable 'exc' (unused-variable)
/log/firmware/firmware/usr/lib/python3.8/asyncio/base_events.py:1207:15: W0212: Access to a protected member _app_transport of a client class (protected-access)
/log/firmware/firmware/usr/lib/python3.8/asyncio/base_events.py:1286:12: W0621: Redefining name 'exceptions' from outer scope (line 41) (redefined-outer-name)
/log/firmware/firmware/usr/lib/python3.8/asyncio/base_events.py:1209:4: R0914: Too many local variables (32/15) (too-many-locals)
/log/firmware/firmware/usr/lib/python3.8/asyncio/base_events.py:1219:16: R0916: Too many boolean expressions in if statement (7/5) (too-many-boolean-expressions)
/log/firmware/firmware/usr/lib/python3.8/asyncio/base_events.py:1215:8: R1702: Too many nested blocks (6/5) (too-many-nested-blocks)
/log/firmware/firmware/usr/lib/python3.8/asyncio/base_events.py:1290:16: R1720: Unnecessary "else" after "raise" (no-else-raise)
/log/firmware/firmware/usr/lib/python3.8/asyncio/base_events.py:1301:18: R1704: Redefining argument with the local name 'family' (redefined-argument-from-local)
/log/firmware/firmware/usr/lib/python3.8/asyncio/base_events.py:1301:26: R1704: Redefining argument with the local name 'proto' (redefined-argument-from-local)
/log/firmware/firmware/usr/lib/python3.8/asyncio/base_events.py:1209:4: R0912: Too many branches (39/12) (too-many-branches)
/log/firmware/firmware/usr/lib/python3.8/asyncio/base_events.py:1209:4: R0915: Too many statements (88/50) (too-many-statements)
/log/firmware/firmware/usr/lib/python3.8/asyncio/base_events.py:1357:41: W0622: Redefining built-in 'type' (redefined-builtin)
/log/firmware/firmware/usr/lib/python3.8/asyncio/base_events.py:1361:8: R1705: Unnecessary "else" after "return" (no-else-return)
/log/firmware/firmware/usr/lib/python3.8/asyncio/base_events.py:1383:12: W0621: Redefining name 'ssl' from outer scope (line 34) (redefined-outer-name)
/log/firmware/firmware/usr/lib/python3.8/asyncio/base_events.py:1376:4: R0914: Too many local variables (26/15) (too-many-locals)
/log/firmware/firmware/usr/lib/python3.8/asyncio/base_events.py:1426:12: C0103: Variable name "fs" doesn't conform to snake_case naming style (invalid-name)
/log/firmware/firmware/usr/lib/python3.8/asyncio/base_events.py:1435:20: C0103: Variable name "af" doesn't conform to snake_case naming style (invalid-name)
/log/firmware/firmware/usr/lib/python3.8/asyncio/base_events.py:1435:52: C0103: Variable name "sa" doesn't conform to snake_case naming style (invalid-name)
/log/firmware/firmware/usr/lib/python3.8/asyncio/base_events.py:1469:24: R1704: Redefining argument with the local name 'sock' (redefined-argument-from-local)
/log/firmware/firmware/usr/lib/python3.8/asyncio/base_events.py:1478:12: R1704: Redefining argument with the local name 'sock' (redefined-argument-from-local)
/log/firmware/firmware/usr/lib/python3.8/asyncio/base_events.py:1484:12: W0212: Access to a protected member _start_serving of a client class (protected-access)
/log/firmware/firmware/usr/lib/python3.8/asyncio/base_events.py:1435:41: W0612: Unused variable 'canonname' (unused-variable)
/log/firmware/firmware/usr/lib/python3.8/asyncio/base_events.py:1376:4: R0912: Too many branches (25/12) (too-many-branches)
/log/firmware/firmware/usr/lib/python3.8/asyncio/base_events.py:1376:4: R0915: Too many statements (57/50) (too-many-statements)
/log/firmware/firmware/usr/lib/python3.8/asyncio/base_events.py:1495:15: W0621: Redefining name 'ssl' from outer scope (line 34) (redefined-outer-name)
/log/firmware/firmware/usr/lib/python3.8/asyncio/base_events.py:1554:4: R0201: Method could be a function (no-self-use)
/log/firmware/firmware/usr/lib/python3.8/asyncio/base_events.py:1567:4: R0914: Too many local variables (16/15) (too-many-locals)
/log/firmware/firmware/usr/lib/python3.8/asyncio/base_events.py:1603:4: R0914: Too many local variables (18/15) (too-many-locals)
/log/firmware/firmware/usr/lib/python3.8/asyncio/base_events.py:1686:16: W0212: Access to a protected member _source_traceback of a client class (protected-access)
/log/firmware/firmware/usr/lib/python3.8/asyncio/base_events.py:1688:16: W0212: Access to a protected member _source_traceback of a client class (protected-access)
/log/firmware/firmware/usr/lib/python3.8/asyncio/base_events.py:1696:16: C0103: Variable name "tb" doesn't conform to snake_case naming style (invalid-name)
/log/firmware/firmware/usr/lib/python3.8/asyncio/base_events.py:1700:16: C0103: Variable name "tb" doesn't conform to snake_case naming style (invalid-name)
/log/firmware/firmware/usr/lib/python3.8/asyncio/base_events.py:1736:19: W0703: Catching too general exception BaseException (broad-except)
/log/firmware/firmware/usr/lib/python3.8/asyncio/base_events.py:1747:19: W0703: Catching too general exception BaseException (broad-except)
/log/firmware/firmware/usr/lib/python3.8/asyncio/base_events.py:1758:23: W0703: Catching too general exception BaseException (broad-except)
/log/firmware/firmware/usr/lib/python3.8/asyncio/base_events.py:1769:11: W0212: Access to a protected member _cancelled of a client class (protected-access)
/log/firmware/firmware/usr/lib/python3.8/asyncio/base_events.py:1781:11: W0212: Access to a protected member _scheduled of a client class (protected-access)
/log/firmware/firmware/usr/lib/python3.8/asyncio/base_events.py:1800:19: W0212: Access to a protected member _cancelled of a client class (protected-access)
/log/firmware/firmware/usr/lib/python3.8/asyncio/base_events.py:1801:20: W0212: Access to a protected member _scheduled of a client class (protected-access)
/log/firmware/firmware/usr/lib/python3.8/asyncio/base_events.py:1810:38: W0212: Access to a protected member _cancelled of a client class (protected-access)
/log/firmware/firmware/usr/lib/python3.8/asyncio/base_events.py:1813:16: W0212: Access to a protected member _scheduled of a client class (protected-access)
/log/firmware/firmware/usr/lib/python3.8/asyncio/base_events.py:1820:19: W0212: Access to a protected member _when of a client class (protected-access)
/log/firmware/firmware/usr/lib/python3.8/asyncio/base_events.py:1830:15: W0212: Access to a protected member _when of a client class (protected-access)
/log/firmware/firmware/usr/lib/python3.8/asyncio/base_events.py:1833:12: W0212: Access to a protected member _scheduled of a client class (protected-access)
/log/firmware/firmware/usr/lib/python3.8/asyncio/base_events.py:1845:15: W0212: Access to a protected member _cancelled of a client class (protected-access)
/log/firmware/firmware/usr/lib/python3.8/asyncio/base_events.py:1850:20: C0103: Variable name "t0" doesn't conform to snake_case naming style (invalid-name)
/log/firmware/firmware/usr/lib/python3.8/asyncio/base_events.py:1851:20: W0212: Access to a protected member _run of a client class (protected-access)
/log/firmware/firmware/usr/lib/python3.8/asyncio/base_events.py:1852:20: C0103: Variable name "dt" doesn't conform to snake_case naming style (invalid-name)
/log/firmware/firmware/usr/lib/python3.8/asyncio/base_events.py:1859:16: W0212: Access to a protected member _run of a client class (protected-access)
/log/firmware/firmware/usr/lib/python3.8/asyncio/base_events.py:1843:12: W0612: Unused variable 'i' (unused-variable)
/log/firmware/firmware/usr/lib/python3.8/asyncio/base_events.py:1784:4: R0912: Too many branches (17/12) (too-many-branches)
/log/firmware/firmware/usr/lib/python3.8/asyncio/base_events.py:384:0: R0904: Too many public methods (37/20) (too-many-public-methods)

-----------------------------------
Your code has been rated at 8.84/10

